Workbook

Sheet Start Here
A1: Forever Save Tracker
A2: Sims 4 on PC. Built for game version 1.128.90.1030 (patch 1.128, September 22, 2026).
A4: At a glance
A5: Mods tracked | B5: =COUNTA('Mod Tracker'!B6:B105) -> 25
A6: Working | B6: =COUNTIF('Mod Tracker'!F6:F105,"Working") -> 0
A7: Testing | B7: =COUNTIF('Mod Tracker'!F6:F105,"Testing") -> 0
A8: Needs update | B8: =COUNTIF('Mod Tracker'!F6:F105,"Needs update") -> 0
A9: Broken | B9: =COUNTIF('Mod Tracker'!F6:F105,"Broken") -> 0
A10: Retired | B10: =COUNTIF('Mod Tracker'!F6:F105,"Retired") -> 0
A11: Not installed yet | B11: =COUNTIF('Mod Tracker'!F6:F105,"Not installed") -> 25
A12: Mods past the stale limit | B12: =COUNTIF('Mod Tracker'!J6:J105,">"&'Mod Tracker'!E3) -> 0
A13: Issues not marked Resolved | B13: =COUNTA('Issue Log'!B6:B205)-COUNTIF('Issue Log'!H6:H205,"Resolved") -> 0
A14: Latest patch logged | B14: =IF(COUNT('Patch Log'!A6:A205)=0,"None",INDEX('Patch Log'!B6:B205,MATCH(MAX('Patch Log'!A6:A205),'Patch Log'!A6:A205,0))) -> 1.128
A15: Last backup | B15: =IF(COUNT(Backups!A6:A205)=0,"None logged yet",MAX(Backups!A6:A205)) -> None logged yet
A16: Days since last backup | B16: =IF(COUNT(Backups!A6:A205)=0,"",TODAY()-MAX(Backups!A6:A205))
A18: How to read this workbook
A19: Yellow cell | B19: A single value for you to fill in or change.
A20: Grey italic row | B20: An example row with made-up values. Overwrite it or delete it.
A21: Black text, no fill | B21: A formula or a fixed fact from the research. Leave formulas alone.
A22: Table rows | B22: Type straight into the rows. Dropdowns list the allowed choices. Each sheet has room for 200 rows.
A24: Steps
A25: Before every patch | B25: Copy your Saves folder and your Mods folder somewhere safe, then add a row on the Backups sheet.
A26: After every patch | B26: Add a row on Patch Log. Turn Script Mods Allowed back on in Game Options, Other. Open the EA forum thread for the new patch and set each affected mod on Mod Tracker to Needs update, Broken or Working. Delete localthumbcache.package after you change Mods.
A27: When something breaks | B27: Add a row on Issue Log. Follow the When a mod breaks section of your install-order page: vanilla test, then the 50/50 method. Write down the fix and mark the issue Resolved.
A28: When you add a mod | B28: Add a row on Mod Tracker and set Status to Testing. Install it and play one Sim day. Then set Status to Working and fill in Version installed, Game version tested on and Last checked.
A29: Once a month | B29: Filter Mod Tracker by Days since check. Highlighted mods are past the stale limit. Open their pages, look for new builds, and update Last checked.
A30: When a Sim joins the world | B30: Add them to Sims Roster with their home world and languages so you can follow the story later.
A32: Assumptions
A33: Stale limit | B33: 45 days is my default. Change it on Mod Tracker, cell E3.
A34: Mod list | B34: Taken from your install-order page. Creators, notes and links come from pages I read between October 9 and 11, 2026. Version, status and date columns are blank for you.
A35: Patch 1.128 | B35: The release date comes from the EA forum thread title. The full version number comes from your screenshot.
A36: Save details | B36: Everything on Save Info comes from the CurseForge page for the save. I did not open the save itself.

Sheet Mod Tracker
A1: Mod Tracker
A2: One row per mod. Pre-filled from your install-order page. Fill in the blank columns as you install and test.
A3: Flag a mod as stale after this many days: | E3: 45 | F3: days since Last checked (my default, change it)
A5: Batch | B5: Mod | C5: Creator | D5: Category | E5: Required? | F5: Status | G5: Version installed | H5: Game version tested on | I5: Last checked | J5: Days since check | K5: Page | L5: Notes
A6: Batch 1 | B6: MC Command Center | C6: Deaderpool | D6: Foundation | E6: Required | F6: Not installed | J6: =IF(I6="","",TODAY()-I6) | L6: Story progression, population and household control. Windows only. Install the core file plus only the modules you want.
A7: Batch 1 | B7: UI Cheats Extension | C7: weerbesu | D7: Foundation | E7: Required | F7: Not installed | J7: =IF(I7="","",TODAY()-I7) | L7: Edit needs, skills, relationships and traits from the pie menu.
A8: Batch 2 | B8: WickedWhims | C8: TURBODRIVER | D8: Adult | E8: Required | F8: Not installed | J8: =IF(I8="","",TODAY()-I8) | K8: Creator page | L8: Includes everything in Wonderful Whims, so skip that one. Delete old WickedWhims files before installing a new release.
A9: Batch 2 | B9: Nisa's Wicked Perversions | C9: Nisa | D9: Adult | E9: Optional | F9: Not installed | J9: =IF(I9="","",TODAY()-I9) | L9: If you use it, match its version to your WickedWhims release. A mismatch causes most WickedWhims error reports.
A10: Batch 2 | B10: Basemental Drugs | C10: Basemental | D10: Adult | E10: Optional | F10: Not installed | J10: =IF(I10="","",TODAY()-I10) | L10: Includes the alcohol features, so you do not need a separate alcohol mod.
A11: Batch 3 | B11: Slice of Life | C11: Sacrificial | D11: Immersion | E11: Required | F11: Not installed | J11: =IF(I11="","",TODAY()-I11) | L11: Personality quirks, illness, injuries and deeper moods.
A12: Batch 3 | B12: Meaningful Stories | C12: roBurky | D12: Immersion | E12: Required | F12: Not installed | J12: =IF(I12="","",TODAY()-I12) | L12: Redesigns the mood and emotion system. Mood mods overlap, so add one at a time.
A13: Batch 3 | B13: First Impressions | C13: Lumpinou | D13: Immersion | E13: Required | F13: Not installed | J13: =IF(I13="","",TODAY()-I13) | L13: Shows trait-based first impressions in the relationship panel.
A14: Batch 3 | B14: XML Injector | C14: Scumbumbo | D14: Immersion | E14: Required | F14: Not installed | J14: =IF(I14="","",TODAY()-I14) | L14: Required by Seasonal Emotions.
A15: Batch 3 | B15: Seasonal Emotions | C15: Ellesimworld | D15: Immersion | E15: Required | F15: Not installed | J15: =IF(I15="","",TODAY()-I15) | L15: Needs XML Injector and Seasons.
A16: Batch 3 | B16: Connected Sims | C16: A.deep.indigo | D16: Immersion | E16: Required | F16: Not installed | J16: =IF(I16="","",TODAY()-I16) | L16: Adds more than 50 ways for friends and family to interact.
A17: Batch 3 | B17: Roommate Stories | C17: Kawaiistacie | D17: Immersion | E17: Required | F17: Not installed | J17: =IF(I17="","",TODAY()-I17) | L17: Roommates keep careers, friends and activities of their own.
A18: Batch 4 | B18: Dine Out Reloaded (public version) | C18: Carl's Guides | D18: Restaurant | E18: Required | F18: Not installed | J18: =IF(I18="","",TODAY()-I18) | K18: Download post | L18: Only edit a restaurant while it is closed. Build the restaurant after installing, or chefs may stand outside. Can get blamed when another mod that touches work shifts is out of date.
A19: Batch 4 | B19: Restaurateur Aspiration | C19: KiaraSims4Mods | D19: Restaurant | E19: Required | F19: Not installed | J19: =IF(I19="","",TODAY()-I19) | K19: Listing | L19: Newbie to 5-star restaurant. The reward trait pays 1,000,000 simoleons.
A20: Batch 4 | B20: My Own Business Aspiration | C20: Not listed | D20: Restaurant | E20: Optional | F20: Not installed | J20: =IF(I20="","",TODAY()-I20) | K20: CurseForge | L20: Alternative that also covers retail and vet clinics. Skip it if you use the Restaurateur aspiration.
A21: Batch 4 | B21: Pharmacist Career | C21: midnitetech | D21: Careers | E21: Optional | F21: Not installed | J21: =IF(I21="","",TODAY()-I21) | L21: Adds an herbalism skill that suits a botanist.
A22: Batch 5 | B22: More Career Opportunities | C22: KiaraSims4Mods | D22: Careers | E22: Required | F22: Not installed | J22: =IF(I22="","",TODAY()-I22) | L22: Adds a large set of new careers.
A23: Batch 5 | B23: midnitetech careers | C23: midnitetech | D23: Careers | E23: Required | F23: Not installed | J23: =IF(I23="","",TODAY()-I23) | L23: Chiropractor, Librarian and other active or hybrid careers. Take the ones you want, one row each.
A24: Batch 5 | B24: Wildlife Biologist career | C24: Not listed | D24: Careers | E24: Required | F24: Not installed | J24: =IF(I24="","",TODAY()-I24) | L24: Updated in late June 2026 on CurseForge.
A25: Batch 5 | B25: Landlord career | C25: Not listed | D25: Careers | E25: Required | F25: Not installed | J25: =IF(I25="","",TODAY()-I25) | L25: Updated in late June 2026 on CurseForge.
A26: Batch 5 | B26: Unlimited Jobs | C26: Not listed | D26: Careers | E26: Optional | F26: Not installed | J26: =IF(I26="","",TODAY()-I26) | K26: CurseForge | L26: Lets a Sim add a second freelance trade without dropping the first.
A27: Batch 6 | B27: Home Regions | C27: Kuttoe | D27: World | E27: Required | F27: Not installed | J27: =IF(I27="","",TODAY()-I27) | K27: Creator page | L27: Keeps walkbys and townies to Sims who live in the local world and spreads townies across worlds. Base Game only. No build naming 1.128 was confirmed.
A28: Batch 6 | B28: Language Barriers | C28: Frankk | D28: World | E28: Required | F28: Not installed | J28: =IF(I28="","",TODAY()-I28) | K28: Creator site | L28: Gives Sims six languages by home world. No 1.128 build confirmed, so check the site before installing.
A29: Batch 7 | B29: More Columns in CAS | C29: Simmattically | D29: CC | E29: Required | F29: Not installed | J29: =IF(I29="","",TODAY()-I29) | L29: Keeps a large CC collection browsable in Create a Sim.
A30: Batch 7 | B30: Sims 4 Tray Importer | C30: Not listed | D30: Tool | E30: Required | F30: Not installed | J30: =IF(I30="","",TODAY()-I30) | L30: Imports and manages saved households and lots.
J31: =IF(I31="","",TODAY()-I31)
J32: =IF(I32="","",TODAY()-I32)
J33: =IF(I33="","",TODAY()-I33)
J34: =IF(I34="","",TODAY()-I34)
J35: =IF(I35="","",TODAY()-I35)
J36: =IF(I36="","",TODAY()-I36)
J37: =IF(I37="","",TODAY()-I37)
J38: =IF(I38="","",TODAY()-I38)
J39: =IF(I39="","",TODAY()-I39)
J40: =IF(I40="","",TODAY()-I40)
J41: =IF(I41="","",TODAY()-I41)
...

Sheet Patch Log
A1: Patch Log
A2: One row per game patch. Add a row the day a patch lands, then fill in the rest as you fix things.
A4: Release date | B4: Patch | C4: Full version | D4: Script Mods Allowed back on? | E4: Backup taken first? | F4: Mods broken | G4: Mods updated | H4: What I did | I4: Minutes spent | J4: Fully fixed on | K4: Days from release to fixed | L4: Notes
A5: 46329 | B5: 1.129 | C5: 1.129.12.1030 | D5: Yes | E5: Yes | F5: Example Mod A, Example Mod B | G5: Example Mod C | H5: Replaced A and B with the new builds, deleted old files | I5: 25 | J5: 46331 | K5: =IF(OR(A5="",J5=""),"",J5-A5) -> 2 | L5: EXAMPLE ROW with made-up values. Overwrite or delete it.
A6: 46287 | B6: 1.128 | C6: 1.128.90.1030 | K6: =IF(OR(A6="",J6=""),"",J6-A6) | L6: Your current version, from your screenshot. Release date from the EA forum thread title.
K7: =IF(OR(A7="",J7=""),"",J7-A7)
K8: =IF(OR(A8="",J8=""),"",J8-A8)
K9: =IF(OR(A9="",J9=""),"",J9-A9)
K10: =IF(OR(A10="",J10=""),"",J10-A10)
K11: =IF(OR(A11="",J11=""),"",J11-A11)
K12: =IF(OR(A12="",J12=""),"",J12-A12)
K13: =IF(OR(A13="",J13=""),"",J13-A13)
K14: =IF(OR(A14="",J14=""),"",J14-A14)
K15: =IF(OR(A15="",J15=""),"",J15-A15)
K16: =IF(OR(A16="",J16=""),"",J16-A16)
K17: =IF(OR(A17="",J17=""),"",J17-A17)
K18: =IF(OR(A18="",J18=""),"",J18-A18)
... K205: =IF(OR(A205="",J205=""),"",J205-A205)

Sheet Issue Log
A1: Issue Log
A2: One row per problem. The fix you write down today saves you the 50/50 hunt next time.
A4: Date seen | B4: Symptom | C4: Game version | D4: Suspected mod | E4: Test used | F4: 50/50 rounds | G4: Fix | H4: Status | I4: Date resolved | J4: Days open | K4: Notes
A5: 46307 | B5: Chefs stand outside the restaurant and never cook | C5: 1.128.90.1030 | D5: Dine Out Reloaded | E5: None yet | F5: 0 | G5: Rebuilt the restaurant after Dine Out Reloaded was installed | H5: Resolved | I5: 46307 | J5: =IF(A5="","",IF(I5="",TODAY()-A5,I5-A5)) -> 0 | K5: EXAMPLE ROW with made-up values. Overwrite or delete it.
J6: =IF(A6="","",IF(I6="",TODAY()-A6,I6-A6))
J7: =IF(A7="","",IF(I7="",TODAY()-A7,I7-A7))
J8: =IF(A8="","",IF(I8="",TODAY()-A8,I8-A8))
J9: =IF(A9="","",IF(I9="",TODAY()-A9,I9-A9))
J10: =IF(A10="","",IF(I10="",TODAY()-A10,I10-A10))
J11: =IF(A11="","",IF(I11="",TODAY()-A11,I11-A11))
J12: =IF(A12="","",IF(I12="",TODAY()-A12,I12-A12))
J13: =IF(A13="","",IF(I13="",TODAY()-A13,I13-A13))
J14: =IF(A14="","",IF(I14="",TODAY()-A14,I14-A14))
J15: =IF(A15="","",IF(I15="",TODAY()-A15,I15-A15))
J16: =IF(A16="","",IF(I16="",TODAY()-A16,I16-A16))
J17: =IF(A17="","",IF(I17="",TODAY()-A17,I17-A17))
... J205: =IF(A205="","",IF(I205="",TODAY()-A205,I205-A205))

Sheet Backups
A1: Backups
A2: Log every copy of your Saves folder. Back up before each patch and before each batch of new mods.
A4: Date | B4: Reason | C4: Game version | D4: Where the copy is | E4: What was copied | F4: Mods snapshot (file name) | G4: Notes
A5: 46307 | B5: Before a patch | C5: 1.128.90.1030 | D5: D:\Backups\Sims4\2026-10-12 | E5: Saves and Mods | F5: mods-2026-10-12.zip | G5: EXAMPLE ROW with made-up values. Overwrite or delete it.

Sheet Save Info
A1: Save Info
A2: Facts about the save file you downloaded. Yellow cells are for you to fill in.
A4: Save name | B4: Ultimate Save (NO CC)
A5: Creator | B5: PlumbobKingdom
A6: Source page | B6: CurseForge page
A7: File date on the page | B7: 46215
A8: Game version | B8: 1.128.90.1030
A9: Language file you installed
A10: Save slot name in the game
A11: Date you started this save
A12: Mods or CC the save requires | B12: None, according to the page. The author used T.O.O.L. to build it, and you do not need it to play.
A13: Packs | B13: The page does not list required packs. Objects from packs you do not own show up missing.
A14: Author's status note | B14: Work in progress. More worlds are planned for future packs.
A15: Known issue | B15: Calendar holidays can make Sims miss work. Fix: open the calendar, set the filter to Holidays, choose Edit on each holiday, and delete any holiday whose edit screen will not open. You can recreate it afterward.
A16: Where to put the file | B16: The page does not say. The game reads saves from Documents\Electronic Arts\The Sims 4\saves.
A17: Compatible versions listed | B17: The page lists 1.124.63 at the top and 115 more versions. I could not see whether 1.128 is among them.

Sheet Sims Roster
A1: Sims Roster
A2: One row per Sim you want to follow. Add them as they join the world.
A4: Sim name | B4: Household | C4: Home world | D4: Life stage | E4: Role in the story | F4: Aspiration | G4: Career | H4: Languages | I4: Date added | J4: Notes
A5: Ana Reyes | B5: Reyes | C5: Willow Creek | D5: Adult | E5: Neighbor who runs the bakery | F5: Friend of the Family | G5: Baker | H5: Simlish | I5: 46307 | J5: EXAMPLE ROW with made-up values. Overwrite or delete it.
E6: Main Sim. Restaurant owner and botanist. | F6: Restaurateur | G6: Gardener, Botanist branch | J6: Fill in the name, household, home world and languages.
